<?xml version="1.0" ?>
<!-- =================================================================================== -->
<!-- |    This document was autogenerated by xacro from fkuka_lwr4p_worl_no_board.xacro | -->
<!-- |    EDITING THIS FILE BY HAND IS NOT RECOMMENDED                                 | -->
<!-- =================================================================================== -->
<robot name="fkuka_lwr4p_world" xmlns:xacro="http://www.ros.org/wiki/xacro">
  <!-- BASE -->
  <!-- camera sensor for visual servoing added on 09/05/2019 by HUAXIN-->
  <joint name="camera_joint" type="fixed">
    <origin rpy="0 0 0" xyz="0 0 0.1"/>
    <parent link="fkuka_lwr4p_A6"/>
    <child link="camera_link"/>
  </joint>
  <link name="camera_link">
    <collision>
      <geometry>
        <box size="0.05 0.05 0.05"/>
      </geometry>
    </collision>
    <visual>
      <geometry>
        <box size="0.05 0.05 0.05"/>
      </geometry>
      <material name="camred">
        <color rgba="0.8 0.2 0.2 1"/>
      </material>
    </visual>
    <inertial>
      <mass value="1e-5"/>
      <origin rpy="0 0 0" xyz="0 0 0"/>
      <inertia ixx="1e-6" ixy="0" ixz="0" iyy="1e-6" iyz="0" izz="1e-6"/>
    </inertial>
  </link>
  <joint name="gz_camera_joint" type="fixed">
    <origin rpy="0 -1.57079632679 -1.57079632679" xyz="0 0 0"/>
    <parent link="camera_link"/>
    <child link="gz_camera_link"/>
  </joint>
  <link name="gz_camera_link"/>
  <!-- Gazebo's camera -->
  <gazebo reference="gz_camera_link">
    <sensor name="mycam" type="camera">
      <update_rate>30.0</update_rate>
      <!--
      <update_rate>60.0</update_rate>
-->
      <camera name="head">
        <!-- NOTE: this is the angular opening of the camera. From this it follows that the focal length is: -->
        <!-- f = wx/2 * cotan(fov/2)    where fov is the opening angle [rad] and wx is the width [pix] of the image -->
        <horizontal_fov>1.3962634</horizontal_fov>
        <image>
          <width>800</width>
          <height>800</height>
          <format>R8G8B8</format>
        </image>
        <clip>
          <near>0.02</near>
          <far>300</far>
        </clip>
        <noise>
          <type>gaussian</type>
          <!-- Noise is sampled independently per pixel on each frame.
               That pixel's noise value is added to each of its color
               channels, which at that point lie in the range [0,1]. -->
          <mean>0.0</mean>
          <stddev>0.007</stddev>
        </noise>
      </camera>
      <plugin filename="libgazebo_ros_camera.so" name="camera_controller">
        <alwaysOn>true</alwaysOn>
        <updateRate>0.0</updateRate>
        <cameraName>fkuka_lwr4p/camera1</cameraName>
        <imageTopicName>image_raw</imageTopicName>
        <cameraInfoTopicName>camera_info</cameraInfoTopicName>
        <frameName>camera_link</frameName>
        <!-- <hackBaseline>0.07</hackBaseline> -->
        <hackBaseline>0.0</hackBaseline>
        <distortionK1>0.0</distortionK1>
        <distortionK2>0.0</distortionK2>
        <distortionK3>0.0</distortionK3>
        <distortionT1>0.0</distortionT1>
        <distortionT2>0.0</distortionT2>
      </plugin>
    </sensor>
  </gazebo>
  <link name="world"/>
  <link name="fkuka_lwr4p_base_link"/>
  <link name="fkuka_lwr4p_base">
    <inertial>
      <mass value="2.7"/>
      <origin rpy="0 0 0" xyz="0 0 0.055"/>
      <inertia ixx="0.00603" ixy="0" ixz="0" iyy="0.00603" iyz="0" izz="0.006615"/>
    </inertial>
    <collision name="base_c0">
      <origin rpy="0 0 0" xyz="0 0 0.055"/>
      <geometry>
        <cylinder length="0.11" radius="0.07"/>
      </geometry>
    </collision>
    <visual name="vis0_lbr4_base">
      <origin rpy="0 0 0" xyz="0 0 0"/>
      <geometry>
        <mesh filename="package://fkuka_lwr4p_description_camera/meshes/base.dae"/>
      </geometry>
    </visual>
  </link>
  <joint name="fkuka_lwr4p_base_joint" type="fixed">
    <parent link="fkuka_lwr4p_base_link"/>
    <child link="fkuka_lwr4p_base"/>
  </joint>
  <!-- LINKS -->
  <link name="fkuka_lwr4p_A1">
    <inertial>
      <mass value="2.7082"/>
      <origin rpy="0 0 0" xyz="0 0.01698 -0.05913"/>
      <inertia ixx="0.0123449" ixy="0" ixz="0" iyy="0.0123449" iyz="0" izz="3.9396351"/>
    </inertial>
    <collision name="A1_c0">
      <origin rpy="0 0 0" xyz="0 0 -0.1"/>
      <geometry>
        <cylinder length="0.2" radius="0.07"/>
      </geometry>
      <!--surface_material: lwr_surface-->
    </collision>
    <collision name="A1_c1">
      <origin rpy="0 0 0" xyz="0 0 0"/>
      <geometry>
        <sphere radius="0.1"/>
      </geometry>
      <!--surface_material: lwr_surface-->
    </collision>
    <visual name="vis0_lbr4_A1">
      <origin rpy="0 0 0" xyz="0 0 0"/>
      <geometry>
        <mesh filename="package://fkuka_lwr4p_description_camera/meshes/A1.dae"/>
      </geometry>
    </visual>
  </link>
  <link name="fkuka_lwr4p_A2">
    <inertial>
      <mass value="2.71"/>
      <origin rpy="0 0 0" xyz="0 0.1109 0.0141"/>
      <inertia ixx="0.0123531" ixy="0" ixz="0" iyy="0.0123531" iyz="0" izz="3.9396395"/>
    </inertial>
    <collision name="A2_c0">
      <origin rpy="-1.57079632679 0 0" xyz="0 0.1 0"/>
      <geometry>
        <cylinder length="0.2" radius="0.07"/>
      </geometry>
      <!--surface_material: lwr_surface-->
    </collision>
    <visual name="vis0_lbr4_A2">
      <origin rpy="0 0 0" xyz="0 0 0"/>
      <geometry>
        <mesh filename="package://fkuka_lwr4p_description_camera/meshes/A2.dae"/>
      </geometry>
    </visual>
  </link>
  <link name="fkuka_lwr4p_E1">
    <inertial>
      <mass value="2.5374"/>
      <origin rpy="0 0 0" xyz="0 -0.01628 0.06621"/>
      <inertia ixx="0.0115663" ixy="0" ixz="0" iyy="0.0115663" iyz="0" izz="1.5369966"/>
    </inertial>
    <collision name="E1_c0">
      <origin rpy="0 0 0" xyz="0 0 0.1"/>
      <geometry>
        <cylinder length="0.2" radius="0.07"/>
      </geometry>
      <!--surface_material: lwr_surface-->
    </collision>
    <collision name="E1_c1">
      <origin rpy="0 0 0" xyz="0 0 0.2"/>
      <geometry>
        <sphere radius="0.1"/>
      </geometry>
      <!--surface_material: lwr_surface-->
    </collision>
    <visual name="vis0_lbr4_E1">
      <origin rpy="0 0 0" xyz="0 0 0.2"/>
      <geometry>
        <mesh filename="package://fkuka_lwr4p_description_camera/meshes/E1.dae"/>
      </geometry>
    </visual>
  </link>
  <link name="fkuka_lwr4p_A3">
    <inertial>
      <mass value="2.5053"/>
      <origin rpy="0 0 0" xyz="0 -0.10538 0.01525"/>
      <inertia ixx="0.01142" ixy="0" ixz="0" iyy="0.01142" iyz="0" izz="1.536918"/>
    </inertial>
    <collision name="A3_c0">
      <origin rpy="-1.57079632679 0 0" xyz="0 -0.1 0"/>
      <geometry>
        <cylinder length="0.2" radius="0.07"/>
      </geometry>
      <!--surface_material: lwr_surface-->
    </collision>
    <visual name="vis0_lbr4_A3">
      <origin rpy="0 0 0" xyz="0 0 0"/>
      <geometry>
        <mesh filename="package://fkuka_lwr4p_description_camera/meshes/A3.dae"/>
      </geometry>
    </visual>
  </link>
  <link name="fkuka_lwr4p_A4">
    <inertial>
      <mass value="1.3028"/>
      <origin rpy="0 0 0" xyz="0 0.01566 0.12511"/>
      <inertia ixx="0.0055152" ixy="0" ixz="0" iyy="0.0055152" iyz="0" izz="0.6011519"/>
    </inertial>
    <collision name="A4_c0">
      <origin rpy="0 0 0" xyz="0 0 0.065"/>
      <geometry>
        <cylinder length="0.13" radius="0.07"/>
      </geometry>
      <!--surface_material: lwr_surface-->
    </collision>
    <visual name="vis0_lbr4_A4">
      <origin rpy="0 0 0" xyz="0 0 0.19"/>
      <geometry>
        <mesh filename="package://fkuka_lwr4p_description_camera/meshes/A4.dae"/>
      </geometry>
    </visual>
  </link>
  <link name="fkuka_lwr4p_A5">
    <inertial>
      <mass value="1.5686"/>
      <origin rpy="0 0 0" xyz="0 0.00283 -0.00228"/>
      <inertia ixx="0.0040156" ixy="0" ixz="0" iyy="0.0040156" iyz="0" izz="0.5783556"/>
    </inertial>
    <collision name="A5_c0">
      <origin rpy="0 0 0" xyz="0 -0.005 -0.0075"/>
      <geometry>
        <sphere radius="0.085"/>
      </geometry>
      <!--surface_material: lwr_surface-->
    </collision>
    <visual name="vis0_lbr4_A5">
      <origin rpy="0 0 0" xyz="0 0 0"/>
      <geometry>
        <mesh filename="package://fkuka_lwr4p_description_camera/meshes/A5.dae"/>
      </geometry>
    </visual>
  </link>
  <link name="fkuka_lwr4p_A6">
    <inertial>
      <mass value="0.1943"/>
      <origin rpy="0 0 0" xyz="0 0 0.06031"/>
      <inertia ixx="0.0000923" ixy="0" ixz="0" iyy="0.0000923" iyz="0" izz="0.5744954"/>
    </inertial>
    <collision name="A6_c0">
      <origin rpy="0 0 0" xyz="0 0 0.0685"/>
      <geometry>
        <cylinder length="0.023" radius="0.0405"/>
      </geometry>
      <!--surface_material: lwr_surface-->
    </collision>
    <visual name="vis0_lbr4_A6_apftn">
      <origin rpy="0 0 0" xyz="0 0 0"/>
      <material name="vis0_lbr4_A6_apftn_mat">
        <color rgba="0.176499992609 0.176499992609 0.176499992609 1"/>
      </material>
      <geometry>
        <mesh filename="package://fkuka_lwr4p_description_camera/meshes/A6.dae"/>
      </geometry>
    </visual>
  </link>
  <!-- JOINTS -->
  <joint name="fkuka_lwr4p_a1_joint" type="revolute">
    <parent link="fkuka_lwr4p_base"/>
    <child link="fkuka_lwr4p_A1"/>
    <origin rpy="0 0 0" xyz="0 0 0.31"/>
    <axis xyz="0 0 1"/>
    <limit effort="1000" lower="-6.28318530718" upper="6.28318530718" velocity="1000"/>
    <!-- WARNING + TEMP: this is just for debugging purposes -->
    <dynamics damping="0.0" friction="0.0"/>
  </joint>
  <joint name="fkuka_lwr4p_a2_joint" type="revolute">
    <parent link="fkuka_lwr4p_A1"/>
    <child link="fkuka_lwr4p_A2"/>
    <origin rpy="1.57079632679 0 0" xyz="0 0 0"/>
    <axis xyz="0 0 1"/>
    <limit effort="1000" lower="-6.28318530718" upper="6.28318530718" velocity="1000"/>
    <!-- WARNING + TEMP: this is just for debugging purposes -->
    <dynamics damping="0.0" friction="0.0"/>
  </joint>
  <joint name="fkuka_lwr4p_e1_joint" type="revolute">
    <parent link="fkuka_lwr4p_A2"/>
    <child link="fkuka_lwr4p_E1"/>
    <origin rpy="-1.57079632679 0 0" xyz="0 0.2 0"/>
    <axis xyz="0 0 1"/>
    <limit effort="1000" lower="-6.28318530718" upper="6.28318530718" velocity="1000"/>
    <!-- WARNING + TEMP: this is just for debugging purposes -->
    <dynamics damping="0.0" friction="0.0"/>
  </joint>
  <joint name="fkuka_lwr4p_a3_joint" type="revolute">
    <parent link="fkuka_lwr4p_E1"/>
    <child link="fkuka_lwr4p_A3"/>
    <origin rpy="-1.57079632679 0 0" xyz="0 0 0.2"/>
    <axis xyz="0 0 1"/>
    <limit effort="1000" lower="-6.28318530718" upper="6.28318530718" velocity="1000"/>
    <!-- WARNING + TEMP: this is just for debugging purposes -->
    <dynamics damping="0.0" friction="0.0"/>
  </joint>
  <joint name="fkuka_lwr4p_a4_joint" type="revolute">
    <parent link="fkuka_lwr4p_A3"/>
    <child link="fkuka_lwr4p_A4"/>
    <origin rpy="1.57079632679 0 0" xyz="0 -0.2 0"/>
    <axis xyz="0 0 1"/>
    <limit effort="1000" lower="-6.28318530718" upper="6.28318530718" velocity="1000"/>
    <!-- WARNING + TEMP: this is just for debugging purposes -->
    <dynamics damping="0.0" friction="0.0"/>
  </joint>
  <joint name="fkuka_lwr4p_a5_joint" type="revolute">
    <parent link="fkuka_lwr4p_A4"/>
    <child link="fkuka_lwr4p_A5"/>
    <origin rpy="1.57079632679 0 0" xyz="0 0 0.19"/>
    <axis xyz="0 0 1"/>
    <limit effort="1000" lower="-6.28318530718" upper="6.28318530718" velocity="1000"/>
    <!-- WARNING + TEMP: this is just for debugging purposes -->
    <dynamics damping="0.0" friction="0.0"/>
  </joint>
  <joint name="fkuka_lwr4p_a6_joint" type="revolute">
    <parent link="fkuka_lwr4p_A5"/>
    <child link="fkuka_lwr4p_A6"/>
    <origin rpy="-1.57079632679 0 0" xyz="0 0 0"/>
    <axis xyz="0 0 1"/>
    <limit effort="1000" lower="-6.28318530718" upper="6.28318530718" velocity="1000"/>
    <!-- WARNING + TEMP: this is just for debugging purposes -->
    <dynamics damping="0.0" friction="0.0"/>
  </joint>
  <gazebo>
    <plugin filename="liblwr_hw_gazebo_plugin.so" name="fkuka_lwr4p_lwr4p_hw_sim">
      <!-- <plugin name="${name}_lwr4p_hw_sim" filename="libgazebo_ros_control.so"> -->
      <robotNamespace>fkuka_lwr4p</robotNamespace>
    </plugin>
  </gazebo>
  <gazebo reference="fkuka_lwr4p_base">
    <gravity>true</gravity>
    <!-- <material>Gazebo/Orange</material> -->
  </gazebo>
  <gazebo reference="fkuka_lwr4p_A1">
    <gravity>true</gravity>
    <!-- <material>Gazebo/Orange</material> -->
  </gazebo>
  <gazebo reference="fkuka_lwr4p_A2">
    <gravity>true</gravity>
    <!-- <material>Gazebo/Orange</material> -->
  </gazebo>
  <gazebo reference="fkuka_lwr4p_E1">
    <gravity>true</gravity>
    <!-- <material>Gazebo/Orange</material> -->
  </gazebo>
  <gazebo reference="fkuka_lwr4p_A3">
    <gravity>true</gravity>
    <!-- <material>Gazebo/Orange</material> -->
  </gazebo>
  <gazebo reference="fkuka_lwr4p_A4">
    <gravity>true</gravity>
    <!-- <material>Gazebo/Orange</material> -->
  </gazebo>
  <gazebo reference="fkuka_lwr4p_A5">
    <gravity>true</gravity>
    <!-- <material>Gazebo/Orange</material> -->
  </gazebo>
  <gazebo reference="fkuka_lwr4p_A6">
    <gravity>true</gravity>
    <!-- <material>Gazebo/Grey</material> -->
  </gazebo>
  <gazebo reference="fkuka_lwr4p_a1_joint">
    <damping> 1 </damping>
    <friction> 10 </friction>
  </gazebo>
  <transmission name="fkuka_lwr4p_a1_trans">
    <type>transmission_interface/SimpleTransmission</type>
    <joint name="fkuka_lwr4p_a1_joint">
      <!-- <hardwareInterface>hardware_interface/${Interface30}</hardwareInterface> -->
      <hardwareInterface>hardware_interface/PositionJointInterface</hardwareInterface>
    </joint>
    <actuator name="fkuka_lwr4p_a1_motor">
      <mechanicalReduction>1</mechanicalReduction>
    </actuator>
  </transmission>
  <transmission name="fkuka_lwr4p_a2_trans">
    <type>transmission_interface/SimpleTransmission</type>
    <joint name="fkuka_lwr4p_a2_joint">
      <!-- <hardwareInterface>hardware_interface/${Interface30}</hardwareInterface> -->
      <hardwareInterface>hardware_interface/PositionJointInterface</hardwareInterface>
    </joint>
    <actuator name="fkuka_lwr4p_a2_motor">
      <mechanicalReduction>1</mechanicalReduction>
    </actuator>
  </transmission>
  <transmission name="fkuka_lwr4p_e1_trans">
    <type>transmission_interface/SimpleTransmission</type>
    <joint name="fkuka_lwr4p_e1_joint">
      <!-- <hardwareInterface>hardware_interface/${Interface30}</hardwareInterface> -->
      <hardwareInterface>hardware_interface/PositionJointInterface</hardwareInterface>
    </joint>
    <actuator name="fkuka_lwr4p_e1_motor">
      <mechanicalReduction>1</mechanicalReduction>
    </actuator>
  </transmission>
  <transmission name="fkuka_lwr4p_a3_trans">
    <type>transmission_interface/SimpleTransmission</type>
    <joint name="fkuka_lwr4p_a3_joint">
      <!-- <hardwareInterface>hardware_interface/${Interface30}</hardwareInterface> -->
      <hardwareInterface>hardware_interface/PositionJointInterface</hardwareInterface>
    </joint>
    <actuator name="fkuka_lwr4p_a3_motor">
      <mechanicalReduction>1</mechanicalReduction>
    </actuator>
  </transmission>
  <transmission name="fkuka_lwr4p_a4_trans">
    <type>transmission_interface/SimpleTransmission</type>
    <joint name="fkuka_lwr4p_a4_joint">
      <!-- <hardwareInterface>hardware_interface/${Interface30}</hardwareInterface> -->
      <hardwareInterface>hardware_interface/PositionJointInterface</hardwareInterface>
    </joint>
    <actuator name="fkuka_lwr4p_a4_motor">
      <mechanicalReduction>1</mechanicalReduction>
    </actuator>
  </transmission>
  <transmission name="fkuka_lwr4p_a5_trans">
    <type>transmission_interface/SimpleTransmission</type>
    <joint name="fkuka_lwr4p_a5_joint">
      <!-- <hardwareInterface>hardware_interface/${Interface30}</hardwareInterface> -->
      <hardwareInterface>hardware_interface/PositionJointInterface</hardwareInterface>
    </joint>
    <actuator name="fkuka_lwr4p_a5_motor">
      <mechanicalReduction>1</mechanicalReduction>
    </actuator>
  </transmission>
  <transmission name="fkuka_lwr4p_a6_trans">
    <type>transmission_interface/SimpleTransmission</type>
    <joint name="fkuka_lwr4p_a6_joint">
      <!-- <hardwareInterface>hardware_interface/${Interface30}</hardwareInterface> -->
      <hardwareInterface>hardware_interface/PositionJointInterface</hardwareInterface>
    </joint>
    <actuator name="fkuka_lwr4p_a6_motor">
      <mechanicalReduction>1</mechanicalReduction>
    </actuator>
  </transmission>
  <joint name="world_joint" type="fixed">
    <parent link="world"/>
    <child link="fkuka_lwr4p_base_link"/>
    <origin rpy="0 0 0" xyz="0 0 0"/>
  </joint>
</robot>
